<?xml version="1.0"?>
<robot name="turtlebot3_tunnel" xmlns:xacro="http://ros.org/wiki/xacro">

  <link name="base_footprint"/>
  
  <joint name="base_joint" type="fixed">
    <parent link="base_footprint"/>
    <child link="base_link"/>
    <origin xyz="0 0 0" rpy="0 0 0"/>
  </joint>

  <link name="base_link">
    <visual>
      <geometry><box size="0.281 0.306 0.141"/></geometry>
      <material name="gray"><color rgba="0.5 0.5 0.5 1.0"/></material>
    </visual>
    <collision>
      <geometry><box size="0.281 0.306 0.141"/></geometry>
    </collision>
    <inertial>
      <mass value="1.5"/>
      <inertia ixx="0.01" ixy="0" ixz="0" iyy="0.01" iyz="0" izz="0.01"/>
    </inertial>
  </link>

  <link name="wheel_left_link">
    <visual><geometry><cylinder radius="0.033" length="0.018"/></geometry></visual>
    <collision><geometry><cylinder radius="0.033" length="0.018"/></geometry></collision>
    <inertial><mass value="0.1"/><inertia ixx="0.0001" ixy="0" ixz="0" iyy="0.0001" iyz="0" izz="0.0001"/></inertial>
  </link>
  <joint name="wheel_left_joint" type="continuous">
    <parent link="base_link"/>
    <child link="wheel_left_link"/>
    <origin xyz="0 0.143 -0.07" rpy="-1.5708 0 0"/>
    <axis xyz="0 0 1"/>
  </joint>

  <link name="wheel_right_link">
    <visual><geometry><cylinder radius="0.033" length="0.018"/></geometry></visual>
    <collision><geometry><cylinder radius="0.033" length="0.018"/></geometry></collision>
    <inertial><mass value="0.1"/><inertia ixx="0.0001" ixy="0" ixz="0" iyy="0.0001" iyz="0" izz="0.0001"/></inertial>
  </link>
  <joint name="wheel_right_joint" type="continuous">
    <parent link="base_link"/>
    <child link="wheel_right_link"/>
    <origin xyz="0 -0.143 -0.07" rpy="-1.5708 0 0"/>
    <axis xyz="0 0 1"/>
  </joint>

  <link name="caster_link">
    <collision><geometry><sphere radius="0.03"/></geometry></collision>
    <inertial><mass value="0.1"/><inertia ixx="0.0001" ixy="0" ixz="0" iyy="0.0001" iyz="0" izz="0.0001"/></inertial>
  </link>
  <joint name="caster_joint" type="fixed">
    <parent link="base_link"/>
    <child link="caster_link"/>
    <origin xyz="0.1 0 -0.07" rpy="0 0 0"/>
  </joint>


  <link name="lidar_link"/>
  <joint name="lidar_joint" type="fixed">
    <parent link="base_link"/>
    <child link="lidar_link"/>
    <origin xyz="0.1 0 0.08" rpy="0 0 0"/>
  </joint>


  <joint name="left_camera_joint" type="fixed">
    <origin xyz="0.1 0.05 0.1" rpy="0 -0.8 0.785"/> 
    <parent link="base_link"/>
    <child link="left_camera_link"/>
  </joint>

  <link name="left_camera_link">
    <visual>
      <geometry><box size="0.01 0.01 0.01"/></geometry>
      <material name="dark_gray"><color rgba="0.2 0.2 0.2 1.0"/></material>
    </visual>
    <inertial>
      <mass value="0.001"/>
      <inertia ixx="0.00001" ixy="0" ixz="0" iyy="0.00001" iyz="0" izz="0.00001"/>
    </inertial>
  </link>


  <joint name="right_camera_joint" type="fixed">
    <origin xyz="0.1 -0.05 0.1" rpy="0 -0.8 -0.785"/> 
    <parent link="base_link"/>
    <child link="right_camera_link"/>
  </joint>

  <link name="right_camera_link">
    <visual>
      <geometry><box size="0.01 0.01 0.01"/></geometry>
      <material name="dark_gray"><color rgba="0.2 0.2 0.2 1.0"/></material>
    </visual>
    <inertial>
      <mass value="0.001"/>
      <inertia ixx="0.00001" ixy="0" ixz="0" iyy="0.00001" iyz="0" izz="0.00001"/>
    </inertial>
  </link>


  <gazebo>
    <plugin filename="libignition-gazebo-diff-drive-system.so" name="ignition::gazebo::systems::DiffDrive">
      <left_joint>wheel_left_joint</left_joint>
      <right_joint>wheel_right_joint</right_joint>
      <wheel_separation>0.286</wheel_separation>
      <wheel_radius>0.033</wheel_radius>
      <odom_publish_frequency>30</odom_publish_frequency>
      <topic>cmd_vel</topic>
      <odom_topic>odom</odom_topic>
      <tf_topic>tf</tf_topic>
      <frame_id>odom</frame_id>
      <child_frame_id>base_link</child_frame_id>
    </plugin>
  </gazebo>

  <gazebo reference="caster_link">
    <mu1>0.0</mu1>
    <mu2>0.0</mu2>
  </gazebo>

  <gazebo reference="lidar_link">
    <sensor name="lidar" type="gpu_lidar">
      <update_rate>10</update_rate>
      <topic>scan</topic>
      <lidar>
        <scan>
          <horizontal>
            <samples>360</samples>
            <resolution>1</resolution>
            <min_angle>-3.14159</min_angle>
            <max_angle>3.14159</max_angle>
          </horizontal>
        </scan>
        <range>
          <min>0.12</min>
          <max>10.0</max>
        </range>
      </lidar>
      <always_on>1</always_on>
      <visualize>true</visualize>
    </sensor>
  </gazebo>

  <gazebo reference="left_camera_link">
    <sensor name="left_rgbd_camera" type="rgbd_camera">
      <topic>/left_camera</topic>
      <gz_frame_id>left_camera_link</gz_frame_id>
      <update_rate>15.0</update_rate>
      <camera>
        <horizontal_fov>1.57</horizontal_fov>
        <image>
          <width>640</width>
          <height>480</height>
        </image>
        <clip>
          <near>0.1</near>
          <far>10.0</far>
        </clip>
      </camera>
      <always_on>true</always_on>
      <visualize>true</visualize>
    </sensor>
  </gazebo>

  <gazebo reference="right_camera_link">
    <sensor name="right_rgbd_camera" type="rgbd_camera">
      <topic>/right_camera</topic>
      <gz_frame_id>right_camera_link</gz_frame_id>
      <update_rate>15.0</update_rate>
      <camera>
        <horizontal_fov>1.57</horizontal_fov>
        <image>
          <width>640</width>
          <height>480</height>
        </image>
        <clip>
          <near>0.1</near>
          <far>10.0</far>
        </clip>
      </camera>
      <always_on>true</always_on>
      <visualize>true</visualize>
    </sensor>
  </gazebo>

  <gazebo reference="base_link">
    <light name="robot_light" type="spot">
      <pose>0.1 0 0.1 0 0 0</pose> 
      
      <diffuse>1 1 1 1</diffuse>
      <specular>1 1 1 1</specular>
      <attenuation>
        <range>5</range> <linear>0.1</linear>
      </attenuation>
      
      <direction>1 0 0</direction> 
      
      <pose>0.1 0 0.1 0 -0.3 0</pose> 

      <spot>
        <inner_angle>0.5</inner_angle>
        <outer_angle>1.2</outer_angle> <falloff>1.0</falloff>
      </spot>
    </light>
  </gazebo>

</robot>